[2024-11-24T02:12:17.718+0000] {local_task_job_runner.py:123} INFO - ::group::Pre task execution logs
[2024-11-24T02:12:17.908+0000] {taskinstance.py:2613} INFO - Dependencies all met for dep_context=non-requeueable deps ti=<TaskInstance: greenhouse_gas_behaviour.extract_co2_emission manual__2024-11-24T02:12:07.537759+00:00 [queued]>
[2024-11-24T02:12:17.974+0000] {taskinstance.py:2613} INFO - Dependencies all met for dep_context=requeueable deps ti=<TaskInstance: greenhouse_gas_behaviour.extract_co2_emission manual__2024-11-24T02:12:07.537759+00:00 [queued]>
[2024-11-24T02:12:17.976+0000] {taskinstance.py:2866} INFO - Starting attempt 1 of 1
[2024-11-24T02:12:18.071+0000] {taskinstance.py:2889} INFO - Executing <Task(PythonOperator): extract_co2_emission> on 2024-11-24 02:12:07.537759+00:00
[2024-11-24T02:12:18.109+0000] {warnings.py:112} WARNING - /home/***/.local/lib/python3.12/site-packages/***/task/task_runner/standard_task_runner.py:70: DeprecationWarning: This process (pid=2714) is multi-threaded, use of fork() may lead to deadlocks in the child.
  pid = os.fork()

[2024-11-24T02:12:18.122+0000] {standard_task_runner.py:72} INFO - Started process 2716 to run task
[2024-11-24T02:12:18.126+0000] {standard_task_runner.py:104} INFO - Running: ['***', 'tasks', 'run', 'greenhouse_gas_behaviour', 'extract_co2_emission', 'manual__2024-11-24T02:12:07.537759+00:00', '--job-id', '67', '--raw', '--subdir', 'DAGS_FOLDER/greenhouse_gas_behaviour.py', '--cfg-path', '/tmp/tmpz522d8xc']
[2024-11-24T02:12:18.140+0000] {standard_task_runner.py:105} INFO - Job 67: Subtask extract_co2_emission
[2024-11-24T02:12:18.512+0000] {task_command.py:467} INFO - Running <TaskInstance: greenhouse_gas_behaviour.extract_co2_emission manual__2024-11-24T02:12:07.537759+00:00 [running]> on host 25d920d1683b
[2024-11-24T02:12:19.132+0000] {taskinstance.py:3132} INFO - Exporting env vars: AIRFLOW_CTX_DAG_OWNER='***' AIRFLOW_CTX_DAG_ID='greenhouse_gas_behaviour' AIRFLOW_CTX_TASK_ID='extract_co2_emission' AIRFLOW_CTX_EXECUTION_DATE='2024-11-24T02:12:07.537759+00:00' AIRFLOW_CTX_TRY_NUMBER='1' AIRFLOW_CTX_DAG_RUN_ID='manual__2024-11-24T02:12:07.537759+00:00'
[2024-11-24T02:12:19.141+0000] {logging_mixin.py:190} INFO - Task instance is in running state
[2024-11-24T02:12:19.151+0000] {logging_mixin.py:190} INFO -  Previous state of the Task instance: queued
[2024-11-24T02:12:19.153+0000] {logging_mixin.py:190} INFO - Current task name:extract_co2_emission state:running start_date:2024-11-24 02:12:17.911041+00:00
[2024-11-24T02:12:19.155+0000] {logging_mixin.py:190} INFO - Dag name:greenhouse_gas_behaviour and current dag run status:running
[2024-11-24T02:12:19.158+0000] {taskinstance.py:731} INFO - ::endgroup::
[2024-11-24T02:12:29.215+0000] {taskinstance.py:3311} ERROR - Task failed with exception
Traceback (most recent call last):
  File "/home/airflow/.local/lib/python3.12/site-packages/urllib3/connection.py", line 196, in _new_conn
    sock = connection.create_connection(
           ^^^^^^^^^^^^^^^^^^^^^^^^^^^^^
  File "/home/airflow/.local/lib/python3.12/site-packages/urllib3/util/connection.py", line 60, in create_connection
    for res in socket.getaddrinfo(host, port, family, socket.SOCK_STREAM):
               ^^^^^^^^^^^^^^^^^^^^^^^^^^^^^^^^^^^^^^^^^^^^^^^^^^^^^^^^^^
  File "/usr/local/lib/python3.12/socket.py", line 976, in getaddrinfo
    for res in _socket.getaddrinfo(host, port, family, type, proto, flags):
               ^^^^^^^^^^^^^^^^^^^^^^^^^^^^^^^^^^^^^^^^^^^^^^^^^^^^^^^^^^^
socket.gaierror: [Errno -3] Temporary failure in name resolution

The above exception was the direct cause of the following exception:

Traceback (most recent call last):
  File "/home/airflow/.local/lib/python3.12/site-packages/urllib3/connectionpool.py", line 789, in urlopen
    response = self._make_request(
               ^^^^^^^^^^^^^^^^^^^
  File "/home/airflow/.local/lib/python3.12/site-packages/urllib3/connectionpool.py", line 490, in _make_request
    raise new_e
  File "/home/airflow/.local/lib/python3.12/site-packages/urllib3/connectionpool.py", line 466, in _make_request
    self._validate_conn(conn)
  File "/home/airflow/.local/lib/python3.12/site-packages/urllib3/connectionpool.py", line 1095, in _validate_conn
    conn.connect()
  File "/home/airflow/.local/lib/python3.12/site-packages/urllib3/connection.py", line 615, in connect
    self.sock = sock = self._new_conn()
                       ^^^^^^^^^^^^^^^^
  File "/home/airflow/.local/lib/python3.12/site-packages/urllib3/connection.py", line 203, in _new_conn
    raise NameResolutionError(self.host, self, e) from e
urllib3.exceptions.NameResolutionError: <urllib3.connection.HTTPSConnection object at 0x7f05886ab5c0>: Failed to resolve 'ourworldindata.org' ([Errno -3] Temporary failure in name resolution)

The above exception was the direct cause of the following exception:

Traceback (most recent call last):
  File "/home/airflow/.local/lib/python3.12/site-packages/requests/adapters.py", line 667, in send
    resp = conn.urlopen(
           ^^^^^^^^^^^^^
  File "/home/airflow/.local/lib/python3.12/site-packages/urllib3/connectionpool.py", line 843, in urlopen
    retries = retries.increment(
              ^^^^^^^^^^^^^^^^^^
  File "/home/airflow/.local/lib/python3.12/site-packages/urllib3/util/retry.py", line 519, in increment
    raise MaxRetryError(_pool, url, reason) from reason  # type: ignore[arg-type]
    ^^^^^^^^^^^^^^^^^^^^^^^^^^^^^^^^^^^^^^^^^^^^^^^^^^^
urllib3.exceptions.MaxRetryError: HTTPSConnectionPool(host='ourworldindata.org', port=443): Max retries exceeded with url: /grapher/co-emissions-per-capita.csv?v=1&csvType=full&useColumnShortNames=true (Caused by NameResolutionError("<urllib3.connection.HTTPSConnection object at 0x7f05886ab5c0>: Failed to resolve 'ourworldindata.org' ([Errno -3] Temporary failure in name resolution)"))

During handling of the above exception, another exception occurred:

Traceback (most recent call last):
  File "/home/airflow/.local/lib/python3.12/site-packages/airflow/models/taskinstance.py", line 767, in _execute_task
    result = _execute_callable(context=context, **execute_callable_kwargs)
             ^^^^^^^^^^^^^^^^^^^^^^^^^^^^^^^^^^^^^^^^^^^^^^^^^^^^^^^^^^^^^
  File "/home/airflow/.local/lib/python3.12/site-packages/airflow/models/taskinstance.py", line 733, in _execute_callable
    return ExecutionCallableRunner(
           ^^^^^^^^^^^^^^^^^^^^^^^^
  File "/home/airflow/.local/lib/python3.12/site-packages/airflow/utils/operator_helpers.py", line 252, in run
    return self.func(*args, **kwargs)
           ^^^^^^^^^^^^^^^^^^^^^^^^^^
  File "/home/airflow/.local/lib/python3.12/site-packages/airflow/models/baseoperator.py", line 417, in wrapper
    return func(self, *args, **kwargs)
           ^^^^^^^^^^^^^^^^^^^^^^^^^^^
  File "/home/airflow/.local/lib/python3.12/site-packages/airflow/operators/python.py", line 238, in execute
    return_value = self.execute_callable()
                   ^^^^^^^^^^^^^^^^^^^^^^^
  File "/home/airflow/.local/lib/python3.12/site-packages/airflow/operators/python.py", line 256, in execute_callable
    return runner.run(*self.op_args, **self.op_kwargs)
           ^^^^^^^^^^^^^^^^^^^^^^^^^^^^^^^^^^^^^^^^^^^
  File "/home/airflow/.local/lib/python3.12/site-packages/airflow/utils/operator_helpers.py", line 252, in run
    return self.func(*args, **kwargs)
           ^^^^^^^^^^^^^^^^^^^^^^^^^^
  File "/opt/airflow/dags/greenhouse_gas_behaviour.py", line 31, in extract_co2_emission
    response = requests.get(URL, verify=False)
               ^^^^^^^^^^^^^^^^^^^^^^^^^^^^^^^
  File "/home/airflow/.local/lib/python3.12/site-packages/requests/api.py", line 73, in get
    return request("get", url, params=params, **kwargs)
           ^^^^^^^^^^^^^^^^^^^^^^^^^^^^^^^^^^^^^^^^^^^^
  File "/home/airflow/.local/lib/python3.12/site-packages/requests/api.py", line 59, in request
    return session.request(method=method, url=url, **kwargs)
           ^^^^^^^^^^^^^^^^^^^^^^^^^^^^^^^^^^^^^^^^^^^^^^^^^
  File "/home/airflow/.local/lib/python3.12/site-packages/requests/sessions.py", line 589, in request
    resp = self.send(prep, **send_kwargs)
           ^^^^^^^^^^^^^^^^^^^^^^^^^^^^^^
  File "/home/airflow/.local/lib/python3.12/site-packages/requests/sessions.py", line 703, in send
    r = adapter.send(request, **kwargs)
        ^^^^^^^^^^^^^^^^^^^^^^^^^^^^^^^
  File "/home/airflow/.local/lib/python3.12/site-packages/requests/adapters.py", line 700, in send
    raise ConnectionError(e, request=request)
requests.exceptions.ConnectionError: HTTPSConnectionPool(host='ourworldindata.org', port=443): Max retries exceeded with url: /grapher/co-emissions-per-capita.csv?v=1&csvType=full&useColumnShortNames=true (Caused by NameResolutionError("<urllib3.connection.HTTPSConnection object at 0x7f05886ab5c0>: Failed to resolve 'ourworldindata.org' ([Errno -3] Temporary failure in name resolution)"))
[2024-11-24T02:12:30.416+0000] {logging_mixin.py:190} INFO - Task instance in failure state
[2024-11-24T02:12:30.427+0000] {logging_mixin.py:190} INFO - Task start:2024-11-24 02:12:17.911041+00:00 end:2024-11-24 02:12:30.415453+00:00 duration:12.504412
[2024-11-24T02:12:30.441+0000] {logging_mixin.py:190} INFO - Task:<Task(PythonOperator): extract_co2_emission> dag:<DAG: greenhouse_gas_behaviour> dagrun:<DagRun greenhouse_gas_behaviour @ 2024-11-24 02:12:07.537759+00:00: manual__2024-11-24T02:12:07.537759+00:00, state:running, queued_at: 2024-11-24 02:12:07.635879+00:00. externally triggered: True>
[2024-11-24T02:12:30.444+0000] {logging_mixin.py:190} INFO - Failure caused by HTTPSConnectionPool(host='ourworldindata.org', port=443): Max retries exceeded with url: /grapher/co-emissions-per-capita.csv?v=1&csvType=full&useColumnShortNames=true (Caused by NameResolutionError("<urllib3.connection.HTTPSConnection object at 0x7f05886ab5c0>: Failed to resolve 'ourworldindata.org' ([Errno -3] Temporary failure in name resolution)"))
[2024-11-24T02:12:30.446+0000] {taskinstance.py:1225} INFO - Marking task as FAILED. dag_id=greenhouse_gas_behaviour, task_id=extract_co2_emission, run_id=manual__2024-11-24T02:12:07.537759+00:00, execution_date=20241124T021207, start_date=20241124T021217, end_date=20241124T021230
[2024-11-24T02:12:30.470+0000] {job.py:229} INFO - Heartbeat recovered after 13.31 seconds
[2024-11-24T02:12:30.593+0000] {taskinstance.py:340} INFO - ::group::Post task execution logs
[2024-11-24T02:12:30.601+0000] {standard_task_runner.py:124} ERROR - Failed to execute job 67 for task extract_co2_emission (HTTPSConnectionPool(host='ourworldindata.org', port=443): Max retries exceeded with url: /grapher/co-emissions-per-capita.csv?v=1&csvType=full&useColumnShortNames=true (Caused by NameResolutionError("<urllib3.connection.HTTPSConnection object at 0x7f05886ab5c0>: Failed to resolve 'ourworldindata.org' ([Errno -3] Temporary failure in name resolution)")); 2716)
Traceback (most recent call last):
  File "/home/airflow/.local/lib/python3.12/site-packages/urllib3/connection.py", line 196, in _new_conn
    sock = connection.create_connection(
           ^^^^^^^^^^^^^^^^^^^^^^^^^^^^^
  File "/home/airflow/.local/lib/python3.12/site-packages/urllib3/util/connection.py", line 60, in create_connection
    for res in socket.getaddrinfo(host, port, family, socket.SOCK_STREAM):
               ^^^^^^^^^^^^^^^^^^^^^^^^^^^^^^^^^^^^^^^^^^^^^^^^^^^^^^^^^^
  File "/usr/local/lib/python3.12/socket.py", line 976, in getaddrinfo
    for res in _socket.getaddrinfo(host, port, family, type, proto, flags):
               ^^^^^^^^^^^^^^^^^^^^^^^^^^^^^^^^^^^^^^^^^^^^^^^^^^^^^^^^^^^
socket.gaierror: [Errno -3] Temporary failure in name resolution

The above exception was the direct cause of the following exception:

Traceback (most recent call last):
  File "/home/airflow/.local/lib/python3.12/site-packages/urllib3/connectionpool.py", line 789, in urlopen
    response = self._make_request(
               ^^^^^^^^^^^^^^^^^^^
  File "/home/airflow/.local/lib/python3.12/site-packages/urllib3/connectionpool.py", line 490, in _make_request
    raise new_e
  File "/home/airflow/.local/lib/python3.12/site-packages/urllib3/connectionpool.py", line 466, in _make_request
    self._validate_conn(conn)
  File "/home/airflow/.local/lib/python3.12/site-packages/urllib3/connectionpool.py", line 1095, in _validate_conn
    conn.connect()
  File "/home/airflow/.local/lib/python3.12/site-packages/urllib3/connection.py", line 615, in connect
    self.sock = sock = self._new_conn()
                       ^^^^^^^^^^^^^^^^
  File "/home/airflow/.local/lib/python3.12/site-packages/urllib3/connection.py", line 203, in _new_conn
    raise NameResolutionError(self.host, self, e) from e
urllib3.exceptions.NameResolutionError: <urllib3.connection.HTTPSConnection object at 0x7f05886ab5c0>: Failed to resolve 'ourworldindata.org' ([Errno -3] Temporary failure in name resolution)

The above exception was the direct cause of the following exception:

Traceback (most recent call last):
  File "/home/airflow/.local/lib/python3.12/site-packages/requests/adapters.py", line 667, in send
    resp = conn.urlopen(
           ^^^^^^^^^^^^^
  File "/home/airflow/.local/lib/python3.12/site-packages/urllib3/connectionpool.py", line 843, in urlopen
    retries = retries.increment(
              ^^^^^^^^^^^^^^^^^^
  File "/home/airflow/.local/lib/python3.12/site-packages/urllib3/util/retry.py", line 519, in increment
    raise MaxRetryError(_pool, url, reason) from reason  # type: ignore[arg-type]
    ^^^^^^^^^^^^^^^^^^^^^^^^^^^^^^^^^^^^^^^^^^^^^^^^^^^
urllib3.exceptions.MaxRetryError: HTTPSConnectionPool(host='ourworldindata.org', port=443): Max retries exceeded with url: /grapher/co-emissions-per-capita.csv?v=1&csvType=full&useColumnShortNames=true (Caused by NameResolutionError("<urllib3.connection.HTTPSConnection object at 0x7f05886ab5c0>: Failed to resolve 'ourworldindata.org' ([Errno -3] Temporary failure in name resolution)"))

During handling of the above exception, another exception occurred:

Traceback (most recent call last):
  File "/home/airflow/.local/lib/python3.12/site-packages/airflow/task/task_runner/standard_task_runner.py", line 117, in _start_by_fork
    ret = args.func(args, dag=self.dag)
          ^^^^^^^^^^^^^^^^^^^^^^^^^^^^^
  File "/home/airflow/.local/lib/python3.12/site-packages/airflow/cli/cli_config.py", line 49, in command
    return func(*args, **kwargs)
           ^^^^^^^^^^^^^^^^^^^^^
  File "/home/airflow/.local/lib/python3.12/site-packages/airflow/utils/cli.py", line 116, in wrapper
    return f(*args, **kwargs)
           ^^^^^^^^^^^^^^^^^^
  File "/home/airflow/.local/lib/python3.12/site-packages/airflow/cli/commands/task_command.py", line 483, in task_run
    task_return_code = _run_task_by_selected_method(args, _dag, ti)
                       ^^^^^^^^^^^^^^^^^^^^^^^^^^^^^^^^^^^^^^^^^^^^
  File "/home/airflow/.local/lib/python3.12/site-packages/airflow/cli/commands/task_command.py", line 256, in _run_task_by_selected_method
    return _run_raw_task(args, ti)
           ^^^^^^^^^^^^^^^^^^^^^^^
  File "/home/airflow/.local/lib/python3.12/site-packages/airflow/cli/commands/task_command.py", line 341, in _run_raw_task
    return ti._run_raw_task(
           ^^^^^^^^^^^^^^^^^
  File "/home/airflow/.local/lib/python3.12/site-packages/airflow/utils/session.py", line 97, in wrapper
    return func(*args, session=session, **kwargs)
           ^^^^^^^^^^^^^^^^^^^^^^^^^^^^^^^^^^^^^^
  File "/home/airflow/.local/lib/python3.12/site-packages/airflow/models/taskinstance.py", line 3005, in _run_raw_task
    return _run_raw_task(
           ^^^^^^^^^^^^^^
  File "/home/airflow/.local/lib/python3.12/site-packages/airflow/models/taskinstance.py", line 273, in _run_raw_task
    TaskInstance._execute_task_with_callbacks(
  File "/home/airflow/.local/lib/python3.12/site-packages/airflow/models/taskinstance.py", line 3159, in _execute_task_with_callbacks
    result = self._execute_task(context, task_orig)
             ^^^^^^^^^^^^^^^^^^^^^^^^^^^^^^^^^^^^^^
  File "/home/airflow/.local/lib/python3.12/site-packages/airflow/models/taskinstance.py", line 3183, in _execute_task
    return _execute_task(self, context, task_orig)
           ^^^^^^^^^^^^^^^^^^^^^^^^^^^^^^^^^^^^^^^
  File "/home/airflow/.local/lib/python3.12/site-packages/airflow/models/taskinstance.py", line 767, in _execute_task
    result = _execute_callable(context=context, **execute_callable_kwargs)
             ^^^^^^^^^^^^^^^^^^^^^^^^^^^^^^^^^^^^^^^^^^^^^^^^^^^^^^^^^^^^^
  File "/home/airflow/.local/lib/python3.12/site-packages/airflow/models/taskinstance.py", line 733, in _execute_callable
    return ExecutionCallableRunner(
           ^^^^^^^^^^^^^^^^^^^^^^^^
  File "/home/airflow/.local/lib/python3.12/site-packages/airflow/utils/operator_helpers.py", line 252, in run
    return self.func(*args, **kwargs)
           ^^^^^^^^^^^^^^^^^^^^^^^^^^
  File "/home/airflow/.local/lib/python3.12/site-packages/airflow/models/baseoperator.py", line 417, in wrapper
    return func(self, *args, **kwargs)
           ^^^^^^^^^^^^^^^^^^^^^^^^^^^
  File "/home/airflow/.local/lib/python3.12/site-packages/airflow/operators/python.py", line 238, in execute
    return_value = self.execute_callable()
                   ^^^^^^^^^^^^^^^^^^^^^^^
  File "/home/airflow/.local/lib/python3.12/site-packages/airflow/operators/python.py", line 256, in execute_callable
    return runner.run(*self.op_args, **self.op_kwargs)
           ^^^^^^^^^^^^^^^^^^^^^^^^^^^^^^^^^^^^^^^^^^^
  File "/home/airflow/.local/lib/python3.12/site-packages/airflow/utils/operator_helpers.py", line 252, in run
    return self.func(*args, **kwargs)
           ^^^^^^^^^^^^^^^^^^^^^^^^^^
  File "/opt/airflow/dags/greenhouse_gas_behaviour.py", line 31, in extract_co2_emission
    response = requests.get(URL, verify=False)
               ^^^^^^^^^^^^^^^^^^^^^^^^^^^^^^^
  File "/home/airflow/.local/lib/python3.12/site-packages/requests/api.py", line 73, in get
    return request("get", url, params=params, **kwargs)
           ^^^^^^^^^^^^^^^^^^^^^^^^^^^^^^^^^^^^^^^^^^^^
  File "/home/airflow/.local/lib/python3.12/site-packages/requests/api.py", line 59, in request
    return session.request(method=method, url=url, **kwargs)
           ^^^^^^^^^^^^^^^^^^^^^^^^^^^^^^^^^^^^^^^^^^^^^^^^^
  File "/home/airflow/.local/lib/python3.12/site-packages/requests/sessions.py", line 589, in request
    resp = self.send(prep, **send_kwargs)
           ^^^^^^^^^^^^^^^^^^^^^^^^^^^^^^
  File "/home/airflow/.local/lib/python3.12/site-packages/requests/sessions.py", line 703, in send
    r = adapter.send(request, **kwargs)
        ^^^^^^^^^^^^^^^^^^^^^^^^^^^^^^^
  File "/home/airflow/.local/lib/python3.12/site-packages/requests/adapters.py", line 700, in send
    raise ConnectionError(e, request=request)
requests.exceptions.ConnectionError: HTTPSConnectionPool(host='ourworldindata.org', port=443): Max retries exceeded with url: /grapher/co-emissions-per-capita.csv?v=1&csvType=full&useColumnShortNames=true (Caused by NameResolutionError("<urllib3.connection.HTTPSConnection object at 0x7f05886ab5c0>: Failed to resolve 'ourworldindata.org' ([Errno -3] Temporary failure in name resolution)"))
[2024-11-24T02:12:30.931+0000] {local_task_job_runner.py:266} INFO - Task exited with return code 1
[2024-11-24T02:12:31.118+0000] {taskinstance.py:3895} INFO - 0 downstream tasks scheduled from follow-on schedule check
[2024-11-24T02:12:31.145+0000] {local_task_job_runner.py:245} INFO - ::endgroup::
